Workbook

Sheet Summary
B1: USME Customer Contract Register - Summary
B3: As-of date (edit to roll forward) | C3: 46305
B4: Documents reviewed | C4: =COUNTA(Register[File Name]) -> 275
B6: Documents by status
B7: Active | C7: =COUNTIF(Register[Status],B7) -> 134
B8: Likely Active - verify | C8: =COUNTIF(Register[Status],B8) -> 18
B9: Unclear - verify | C9: =COUNTIF(Register[Status],B9) -> 12
B10: Expired | C10: =COUNTIF(Register[Status],B10) -> 85
B11: Reference/Superseded | C11: =COUNTIF(Register[Status],B11) -> 26
B13: Active / likely-active documents expiring
B14: Past stated expiry, no auto-renew projection (holdover / verify) | C14: =COUNTIFS(Register[Status],"<>Expired",Register[Status],"<>Reference/Superseded",Register[Days to Expiry],">="&-100000,Register[Days to Expiry],"<="&-1) -> 35
B15: Within 90 days | C15: =COUNTIFS(Register[Status],"<>Expired",Register[Status],"<>Reference/Superseded",Register[Days to Expiry],">="&0,Register[Days to Expiry],"<="&90) -> 10
B16: 91-180 days | C16: =COUNTIFS(Register[Status],"<>Expired",Register[Status],"<>Reference/Superseded",Register[Days to Expiry],">="&91,Register[Days to Expiry],"<="&180) -> 10
B17: 181-365 days | C17: =COUNTIFS(Register[Status],"<>Expired",Register[Status],"<>Reference/Superseded",Register[Days to Expiry],">="&181,Register[Days to Expiry],"<="&365) -> 30
B18: Beyond 12 months | C18: =COUNTIFS(Register[Status],"<>Expired",Register[Status],"<>Reference/Superseded",Register[Days to Expiry],">="&366,Register[Days to Expiry],"<="&100000) -> 74
B19: No determinable expiry date | C19: =COUNTIFS(Register[Status],"<>Expired",Register[Status],"<>Reference/Superseded",Register[Expiration Date],"") -> 5
B21: Documents by type (all)
B22: Amendment | C22: =COUNTIF(Register[Doc Type],B22) -> 45
B23: Extension | C23: =COUNTIF(Register[Doc Type],B23) -> 23
B24: GPO Agreement | C24: =COUNTIF(Register[Doc Type],B24) -> 34
B25: GPO Letter of Participation/SIP | C25: =COUNTIF(Register[Doc Type],B25) -> 34
B26: Master/Rental Agreement | C26: =COUNTIF(Register[Doc Type],B26) -> 100
B27: Notice/Other | C27: =COUNTIF(Register[Doc Type],B27) -> 1
B28: Pricing Exhibit | C28: =COUNTIF(Register[Doc Type],B28) -> 5
B29: Purchase/Sale Agreement | C29: =COUNTIF(Register[Doc Type],B29) -> 7
B30: Rebate Agreement | C30: =COUNTIF(Register[Doc Type],B30) -> 10
B31: Service Agreement/SOW | C31: =COUNTIF(Register[Doc Type],B31) -> 16
B33: Data quality
B34: Confidence: High | C34: =COUNTIF(Register[Confidence],"High") -> 172
B35: Confidence: Medium | C35: =COUNTIF(Register[Confidence],"Medium") -> 101
B36: Confidence: Low | C36: =COUNTIF(Register[Confidence],"Low") -> 2
B37: Read via OCR (scanned PDFs) | C37: =COUNTIF(Register[Text Source],"OCR") -> 98

Sheet Contract Register
A1: Customer Group | B1: Counterparty (as written) | C1: Folder | D1: File Name | E1: Doc Type | F1: Service Lines | G1: GPO / Contract # | H1: USME Entity | I1: Effective Date | J1: Expiration (as stated) | K1: Expiration Date | L1: Exp. Date Source | M1: Projected Term End (auto-renew roll-fwd) | N1: Days to Expiry | O1: Status | P1: Initial Term | Q1: Renewal | R1: Termination | S1: Pricing Basis | T1: Price Increase / Escalator | U1: Rebate / Admin Fee | V1: Commitment / Exclusivity | W1: Payment Terms | X1: Liability / Risk Terms | Y1: Key Notes | Z1: Confidence | AA1: Text Source
A2: Advantus Health Partners (Bon Secours Mercy) | B2: Advantage Health Partners LLC d/b/a Advantus Health Partners (on behalf of AHP and its Buyers) | C2: Advantus | D2: Advantus HP MME_BTS Exp 6.30.28_auto.pdf | E2: GPO Agreement | F2: MME Rental, BTS Rental | G2: Advantus AHP-MM-0034 | H2: US Med-Equip, LLC | I2: 2025-04-14 | J2: 2028-04-13 | K2: 46856 | L2: Contract text | N2: =IF(M2<>"",M2-Summary!$C$3,IF(K2="","",K2-Summary!$C$3)) -> 551 | O2: Active | P2: 3 years | Q2: Auto-renews 1-yr terms until terminated | R2: Either party (Vendor or AHP), 90 days written notice, without penalty; every LOP must allow mutual 90-day no-cause termination; vendor must give 90-day transition | S2: Exhibit B (MME) and B-1 (BTS) daily rates; two tiers: Tier 1 Access (no commitment) and Tier 2 Provider 90% | T2: Fixed for initial 3 years; thereafter vendor may modify B-1 pricing not more than once annually with documentation via written amendment | U2: AHP administrative fee 3% of aggregate purchases; any rebates paid directly to Buyers; Value Add per Exhibit D | V2: Tier 2 requires 90% rental spend commitment, USME primary vendor, business line reviews; 60-day notice/cure before tier reduction | W2: Net 30 from receipt of uncontested invoice, electronic; Buyers pay no late penalties or interest | X2: AHP Exhibit A terms control; Buyers are third-party beneficiaries; mutual consequential damages exclusion; assignment needs consent; audit (vendor pays if >5% under/overcharge); auto liability $1M | Y2: AHP is BSMH-affiliated GPO; covers MME and BTS for participating facilities via LOP. Filename says Exp 6/30/28 but text gives 3-year term from 4/14/2025 (~4/13/2028) with auto-renewal. | Z2: High | AA2: Text
A3: AdventHealth | B3: Adventist Health System Sunbelt Healthcare Corporation d/b/a AdventHealth | C3: AdventHealth | D3: PP-NS-1565 US Med-Equip A1.docx.pdf | E3: Amendment | F3: BTS Rental, Other | G3: Premier PP-NS-1565 | H3: US Med-Equip, LLC | I3: 2025-10-01 | J3: Not stated (follows underlying PP-NS-1565 supplement agreement) | L3: Unknown | N3: =IF(M3<>"",M3-Summary!$C$3,IF(K3="","",K3-Summary!$C$3)) | O3: Active | P3: Not stated | Q3: Not stated | R3: Not stated | S3: Adds one item to Schedule 1: Stryker Medical Extender Kit (item 59739) at $13.11/EA | T3: Not stated | U3: Not stated | V3: Not stated | W3: Not stated | X3: Not stated | Y3: Amendment 1 to AdventHealth GPO supplement agreement under Premier PP-NS-1565 adding a Stryker extender kit; signed 10/24/2025 by Doug Pytlinski (AdventHealth) and Tim Heck (USME). Term and other terms governed by the underlying supplement. | Z3: High | AA3: Text
A4: AdventHealth | B4: Adventist Health System Sunbelt Healthcare Corporation d/b/a AdventHealth | C4: AdventHealth | D4: AdventHealth BTS_Exp_03_01_31.pdf | E4: GPO Letter of Participation/SIP | F4: BTS Rental, MME Rental | G4: Premier PP-NS-1565 (supplement) | H4: US Med-Equip, LLC | I4: 2025-10-01 | J4: 2031-03-01 | K4: 47908 | L4: Contract text | N4: =IF(M4<>"",M4-Summary!$C$3,IF(K4="","",K4-Summary!$C$3)) -> 1603 | O4: Active | P4: ~5.4 years (Oct 1, 2025 to Mar 1, 2031) | Q4: None stated; continues if new Premier GPO award, else Premier terms survive as individual agreement | R4: Either party, 30 days prior written notice; AdventHealth may terminate immediately if Supplier fails credentialing | S4: Schedule B fixed daily rates per model (Premier-based supplement pricing) | T4: Not stated; no pass-through of taxes/tariffs permitted | U4: 2% rebate on aggregate sales + additional 2% multi-service line rebate (BTS + MME primary, 90% first call each, DSO <=30); paid annually 45 days after anniversary | V4: 90% first-call annual purchase commitment for beds/mattresses/therapeutic surfaces rental | W4: Per Premier GPO Agreement; DSO must not exceed 30 days for rebate | X4: KPIs: 98% fill rate, delivery within 2 hrs + drive time, pickup 24 hrs (billing stops on notice), 24-hr replacement; TLS1.2/AES-256 data security, third-party risk review | Y4: Supplement to Premier PP-NS-1565 covering AdventHealth facilities (Schedule A); includes rental equity discount (25%) and lost-equipment buyout policy. Agreement outlasts Premier agreement term. | Z4: High | AA4: Text
A5: AdventHealth | B5: Adventist Health System Sunbelt Healthcare Corporation d/b/a AdventHealth | C5: AdventHealth | D5: AdventHealth_Amendment_Verticles_Exp_03_01_31.pdf | E5: Rebate Agreement | F5: BTS Rental, MME Rental | G5: Premier PP-NS-1565 (Patient Beds-Rental), SP-NS-2139 (Peak Use Rental) | H5: US Med-Equip, LLC | I5: 2026-04-01 | J5: 2031-03-01 | K5: 47908 | L5: Contract text | N5: =IF(M5<>"",M5-Summary!$C$3,IF(K5="","",K5-Summary!$C$3)) -> 1603 | O5: Active | P5: ~5 years (2026-04-01 to 2031-03-01) | Q5: None stated | R5: Either party, without cause, 30 days written notice (all or part / by product); immediate if credentialing fails | S5: Per GPO contracts listed in Exhibit A (Premier PP-NS-1565, SP-NS-2139); 'Master Product Incentive Agreement' AH-CI-6370 | T5: Not stated | U5: 2% rebate on aggregate net sales + additional 2% multi-service-line rebate if USME primary for beds and MME (90% first call), DSO <=30 days; paid 45 days after anniversary | V5: 90% first-call commitment for Patient Beds and Peak Use Rental; no penalty for facility reductions; clinical-issue product removal without liability | W5: Not stated in agreement (rebate conditioned on DSO <=30 days; disputes within 15 days of invoice) | X5: Supplier liability cap = 12 months' fees, carve-outs for injury, indemnity, confidentiality, HIPAA, negligence; broad supplier indemnity; insurance $5M/$10M CGL, $5M auto, $5M EL | Y5: Health-system incentive agreement layering rebates over Premier contracts for all AdventHealth facilities (auto-adds new facilities). Filename says 'Amendment' but document is a new Master Product Incentive Agreement; rebate section cites Exhibit C but rebate is Exhibit B. | Z5: High | AA5: Text
A6: Adventist Health (West) | B6: Adventist Health System/West | C6: Adventist West | D6: AdventistHealth West_MME BTS_Exp 03.31.2029_auto renew.pdf | E6: Amendment | F6: MME Rental, BTS Rental | G6: Direct | H6: US Med-Equip, LLC | I6: 2026-04-01 | J6: Not stated in amendment (filename: 2029-03-31, auto renew) | K6: 47208 | L6: Contract text | N6: =IF(M6<>"",M6-Summary!$C$3,IF(K6="","",K6-Summary!$C$3)) -> 903 | O6: Active | P6: Not stated | Q6: Not stated in amendment (filename indicates auto-renew) | R6: Not stated | S6: Per underlying Equipment Rental Agreement; Non-Owned Facilities load pricing via Exhibit 1.1 Letter of Participation | T6: Not stated | U6: Not stated | V6: Not stated | W6: Not stated | X6: Adventist Health disclaims liability for Non-Owned (affiliate acute) facilities' obligations | Y6: First Amendment replacing Attachment B Covered Facilities (~25 acute facilities in CA/OR/HI plus non-acute entities) and adding a LOP for non-owned affiliates. Base agreement (eff. 4/1/2026) not in this file; expiry taken from filename only. | Z6: Medium | AA6: Text
A7: Adventist Health (West) | B7: Adventist Health System/West | C7: Adventist Health - CA | D7: Adventist Health BTS Exp 3.31.29.pdf | E7: Master/Rental Agreement | F7: MME Rental, BTS Rental, Respiratory, Restraints/Posey | G7: Vizient CE9205, CE7782 (incorporated by reference) | H7: US Med-Equip, LLC | I7: 2026-04-01 | J7: 2029-03-31 | K7: 47208 | L7: Contract text | N7: =IF(M7<>"",M7-Summary!$C$3,IF(K7="","",K7-Summary!$C$3)) -> 903 | O7: Active | P7: 3 years | Q7: Auto-renews successive 1-yr terms | R7: After Initial Term, either party without cause on 60 days written notice; breach with 60-day cure | S7: Daily rates per Attachment A (MME and BTS); Primary Vendor pricing; April 2026 MME rent waived as conversion incentive (skip billing) | T7: Fixed for Initial Term; thereafter up to 3% once per contract year with 30 days notice | U7: USME pays Vizient GPO admin fees and sales reports per Vizient agreements | V7: Primary Vendor: 90%+ of annual rental spend for covered facilities; 120-day cure, then list pricing until cured | W7: Net 30 via ACH/wire; 1.5%/month interest on undisputed past due; credit hold/repossession rights | X7: Customer responsible for loss/damage and must insure at replacement cost; mutual indemnity; no consequential damages; USME GL $1M/$3M; assignment requires USME consent; Delaware law | Y7: Conversion from incumbent across ~30 Adventist Health West acute facilities in CA/OR (Attachment B); 2-hour plus drive time delivery commitment. Filename says BTS but agreement covers both MME and BTS. | Z7: High | AA7: Text
A8: Adventist HealthCare (MD) | B8: Adventist Healthcare (Maryland) | C8: Adventist MD | D8: Adventist_Healthcare_MD_Rental_Agreement_Exp_8_31_2030.pdf | E8: Master/Rental Agreement | F8: BTS Rental | G8: Direct | H8: US Med-Equip, LLC | I8: 2025-09-01 | J8: 2030-08-31 | K8: 47726 | L8: Contract text | N8: =IF(M8<>"",M8-Summary!$C$3,IF(K8="","",K8-Summary!$C$3)) -> 1421 | O8: Active | P8: 5 years | Q8: Auto-renews successive 1-yr terms | R8: Either party, 60 days written notice without cause, only after Initial Term; 60-day cure for breach | S8: Daily rates per Attachment A (Primary Vendor pricing); contract # AD08262025JS | T8: Fixed until 2nd anniversary; then max 1x/yr by greater of 5% or prior-yr Medical Care CPI-U, 30 days notice (email OK) | U8: Not stated | V8: Primary Vendor: 90%+ of annual rental spend; 60-day cure, else list pricing for remaining term | W8: Net 30 via ACH/wire; interest at max legal rate on past due; repossession/credit hold/list pricing on non-payment | X8: Customer liable for loss/damage and must insure equipment at replacement cost; mutual indemnity; no consequential damages; USME CGL $1M/$3M; customer may not assign w/o consent; TX law, Harris County | Y8: Covers Fort Washington MC and White Oak MC (Attachment B). Strong USME-favorable terms incl. escalator and list-price fallback for commitment breach. | Z8: High | AA8: Text
A9: Allegheny Health Network (Highmark Health) | B9: Allegheny Health Network | C9: Allegheny Health - MME | D9: Allegheny MME _Exp_2_28_30.pdf | E9: Master/Rental Agreement | F9: MME Rental, Respiratory | G9: Direct | H9: US Med-Equip, LLC | I9: 2025-03-01 | J9: 2030-02-28 | K9: 47542 | L9: Contract text | N9: =IF(M9<>"",M9-Summary!$C$3,IF(K9="","",K9-Summary!$C$3)) -> 1237 | O9: Active | P9: 5 years | Q9: Auto-renews successive 1-yr terms | R9: Either party without cause on 30 days written notice; 60-day cure for breach | S9: Daily/monthly rental rates per Attachment A (Preferred Vendor pricing; list price shown for safe harbor reporting); Contract #09202024JS | T9: Not stated | U9: Not stated | V9: Preferred vendor: customer to place 90%+ of annual rental spend for Attachment A equipment with USME at Covered Facilities (Att. B); 60-day cure, else then-applicable pricing | W9: Net 30; USME may repossess or put customer on credit hold for non-payment | X9: Customer liable for loss/damage and must insure equipment at replacement cost; full new-equipment cost if not surrendered; broad USME indemnity; no assignment without consent; CGL $1M/$3M | Y9: 5-year preferred-vendor MME deal with 90% spend commitment, but either party can exit on 30 days notice, which weakens the commitment. AHN exhibits C-G (AI, data security, BAA) add obligations. | Z9: High | AA9: Text
A10: Allegheny Health Network (Vizient) | B10: Vizient Supply, LLC for the benefit of Allegheny Health Network (AHN) | C10: Allegheny Health - Beds | D10: AHN US Med-Equip Bariatric Bed Rentals Addendum Exp 2_29_2028.pdf | E10: Amendment | F10: BTS Rental | G10: Vizient CE9205AB (formerly CE3363AB) | H10: US Med-Equip, LLC | I10: 2025-03-01 | J10: 2028-02-29 | K10: 46812 | L10: Contract text | N10: =IF(M10<>"",M10-Summary!$C$3,IF(K10="","",K10-Summary!$C$3)) -> 507 | O10: Active | P10: Not stated (addendum expires 2/29/2028) | Q10: None stated | R10: Vizient may terminate without cause on 90 days written notice; auto-terminates if base agreement CE9205 terminates | S10: Not stated in amendment (per underlying addendum) | T10: Not stated | U10: Not stated | V10: Not stated | W10: Not stated | X10: Not stated | Y10: Amends AHN bariatric & therapeutic beds addendum: extends to 2/29/2028 and re-points base agreement from CE3363 to Vizient CE9205 (dated 3/1/2025); sales to be reported under CE9205. | Z10: High | AA10: Text
A11: Amber Well Health | B11: Amber Well Health Hiawatha | C11: Amber Well | D11: Amber Well Health Hiawatha_Rental_Agreement_Exp_02_28_26.pdf | E11: Master/Rental Agreement | F11: BTS Rental, MME Rental | G11: Direct | H11: US Med-Equip, LLC | I11: 2025-03-01 | J11: 2027-02-28 (current auto-renewal term; initial term ended 2026-02-28) | K11: 46446 | L11: Contract text | N11: =IF(M11<>"",M11-Summary!$C$3,IF(K11="","",K11-Summary!$C$3)) -> 141 | O11: Active | P11: 1 year | Q11: Auto-renews successive 1-yr terms | R11: Either party, 30 days written notice without cause after Initial Term; 60-day cure for breach | S11: Daily/monthly rates per Attachment A; Primary Vendor pricing (BTS + MME cribs) | T11: Fixed until 2nd anniversary (2027-03-01); then max once/yr, greater of 5% or prior-yr Medical Care CPI-U, 30 days notice (email OK) | U11: Not stated | V11: Primary Vendor: 90%+ of annual rental spend; 60-day cure, else list pricing for remainder of term | W11: Net 30; late interest lesser of 1.5%/mo or legal max; credit-hold and list pricing on non-payment | X11: Customer liable for loss/damage and must insure equipment at replacement cost; mutual indemnity; no consequential damages; USME CGL $1M/$3M; full new-unit cost if not surrendered | Y11: Single Kansas critical-access hospital (Hiawatha, KS), contract KS02072025HCH. Mostly BTS (Freedom Wave, Nuvay surfaces) plus cribs. Filename expiry 2/28/26 is end of initial term; auto-renewed. | Z11: High | AA11: OCR
A12: AMG Integrated Healthcare | B12: Houston-AMG Specialty Hospital, Inc. | C12: AMG/Houston | D12: AMG Houston Biomed Service_Exp_06_30_29.pdf | E12: Service Agreement/SOW | F12: Biomed/Repair Service | G12: Direct | H12: US Med-Equip, LLC | I12: 2026-07-01 | J12: 2029-06-30 | K12: 47299 | L12: Contract text | N12: =IF(M12<>"",M12-Summary!$C$3,IF(K12="","",K12-Summary!$C$3)) -> 994 | O12: Active | P12: 3 years | Q12: Auto-renews successive 1-yr terms | R12: Customer may terminate without cause on 60 days written notice at any time; after Initial Term either party 60 days; customer termination for unsatisfactory PM after 30-day cure | S12: Fixed PM fee for customer-owned equipment (Exhibit A): $2,980/month, $35,760/year; parts excluded | T12: Annual CPI-U adjustment, lesser of 3% or CPI-U increase | U12: Not stated | V12: Non-exclusive; no minimum/maximum volume guarantees | W12: Net 30 from receipt of undisputed invoice; 1.5%/month late fee; USME may suspend services for late payment | X12: USME liability capped at total agreement price; no consequential damages; mutual indemnity; insurance $1M/$3M GL & professional; exclusions for misuse, acts of God, customer modifications | Y12: Annual on-site preventive maintenance (inspection, testing, calibration, documentation) on hospital-owned equipment per Exhibit A (e.g., Zoll defibrillators); repairs, parts and software excluded. Contract ID 05052601HP. Customer's anytime 60-day convenience termination undercuts the 3-year term. | Z12: High | AA12: Text
A13: AMG Specialty Hospital | B13: Clear Lake-AMG Specialty Hospital, Inc. | C13: AMG/Clear Lake | D13: AMG Clear Lake Biomed Service_Exp_06_30_29.pdf | E13: Service Agreement/SOW | F13: Biomed/Repair Service | G13: Direct | H13: US Med-Equip, LLC | I13: 2026-07-01 | J13: 2029-06-30 | K13: 47299 | L13: Contract text | N13: =IF(M13<>"",M13-Summary!$C$3,IF(K13="","",K13-Summary!$C$3)) -> 994 | O13: Active | P13: 3 years | Q13: Auto-renews successive 1-yr terms | R13: Customer may terminate without cause on 60 days written notice anytime; after Initial Term either party on 60 days notice; customer may terminate for unsatisfactory PM after 30-day cure | S13: Annual PM (excl. parts) on hospital-owned equipment in Exhibit A: $3,705.63/month, $44,467.50/year (Contract ID 05052601HP) | T13: Annual CPI-U adjustment, capped at lesser of 3% or CPI | U13: None | V13: Non-exclusive; no volume minimums or guarantees | W13: Net 30 from receipt of undisputed invoice; 1.5%/month late fee; USME may suspend services for late payment | X13: USME liability capped at total contract price; no consequential damages; mutual indemnity; CGL/professional $1M/$3M; parts, repairs, software excluded | Y13: Biomed PM-only contract on customer-owned equipment (defibrillators, ECGs, etc.); parts and corrective repairs excluded. Customer has 60-day termination for convenience from day one. | Z13: High | AA13: Text
A14: Ascension (The Resource Group) | B14: Ascension Health Resource and Supply Management Group, LLC (The Resource Group) | C14: GPO/The Resource Group | D14: Resource Group_MME_3_31_2029.pdf | E14: Amendment | F14: MME Rental | G14: The Resource Group USMED-0170211 | H14: US Med-Equip LLC | I14: 2026-04-01 (Amendment 003; agreement dated 2023-02-15) | J14: 2029-03-31 | K14: 47208 | L14: Contract text | N14: =IF(M14<>"",M14-Summary!$C$3,IF(K14="","",K14-Summary!$C$3)) -> 903 | O14: Active | P14: Not stated | Q14: Not stated | R14: Not stated in amendment | S14: Exhibit 1 (Appendix A-2) daily/monthly rates vs list price | T14: Supplier may request price change once annually for material cost changes; 30-day good-faith negotiation, else may remove part number | U14: Contract admin fee 5%; 3% conversion rebate on first 12 months (requires 90% compliance, DSO <=30, non-stackable) | V14: Primary vendor: >=90% of annual MME rental spend (aggregate); up to 25% premium on non-compliant participants after 30-day notice + 60-day cure; 90-day transition | W14: Net 30 via ACH/wire; interest 1.5% on undisputed sums >45 days past due; credit-hold, list pricing, repossession rights | X14: No MFN/pricing parity (special promotions need not be extended); rebate reporting late interest | Y14: Amendment 003 extends Ascension TRG MME agreement to 3/31/2029, raises admin fee to 5%, adds Appendix O primary provider terms. Document contains bank remittance details. | Z14: High | AA14: Text
A15: Atlantic Health System | B15: Atlantic Health System, Inc. | C15: Atlantic Health System | D15: Atlantic Health_BTS_Exp_11_14_30.pdf | E15: Master/Rental Agreement | F15: BTS Rental | G15: Premier PP-NS-1565 (GPO fees traced) | H15: US Med-Equip, LLC | I15: 2025-05-01 (signed 2025-11-12) | J15: 2030-04-30 (5 yrs from effective date; filename says 11/14/30) | K15: 47603 | L15: Contract text | N15: =IF(M15<>"",M15-Summary!$C$3,IF(K15="","",K15-Summary!$C$3)) -> 1298 | O15: Active | P15: 5 years | Q15: Successive 1-yr renewals by mutual written consent | R15: After Initial Term, either party without cause on 30 days written notice; breach with 60-day cure | S15: Attachment A daily/monthly rates; primary vendor pricing (list pricing if 80% commitment not cured in 60 days) | T15: Fixed until 2nd anniversary; then max once/yr, greater of 5% or Medical Care CPI-U, 30 days notice | U15: Quarterly rebate: Yr1 8%, Yrs 2-5+ 3%; requires 80% BTS commitment, DSO <=30, ACH payment; no stacking with other rebates | V15: Primary vendor: 80%+ of annual BTS rental spend; 60-day cure else list pricing | W15: Net 30 via ACH/wire; interest on past due at max legal rate; USME may suspend service | X15: Customer liable for loss/damage of equipment and must insure at replacement cost; mutual indemnity; CGL $1M/$3M; delivery 4 hrs avg, pickup 24 hrs avg; assignment needs consent (customer merger exempt) | Y15: Covers 9 Atlantic facilities in NJ incl. CentraState and Morristown. Filename expiry 11/14/30 conflicts with 5-yr term from 5/1/2025 effective date (text implies 4/30/2030). | Z15: High | AA15: Text
... A21: Centra Health | B21: Centra Health | C21: Centra Health | D21: Centra Health BTS Exp 12_21_2028.pdf | E21: Master/Rental Agreement | F21: BTS Rental, MME Rental, Asset Mgmt/On-site | G21: Direct (Contract # CH010324JS) | H21: US Med-Equip, LLC | I21: 2023-12-22 | J21: 2028-12-21 | K21: 47108 | L21: Contract text | N21: =IF(M21<>"",M21-Summary!$C$3,IF(K21="","",K21-Summary!$C$3)) -> 803 | O21: Active | P21: 5 years | Q21: Auto-renews successive 1-yr terms | R21: Either party without cause on 60 days notice, only after Initial Term | S21: Primary Vendor daily rates per Attachment A (Freedom 1000 $55.00, Freedom 500 $27.55, Pronova-O2 $1,400); 25% Rental Equity Discount option | T21: Fixed 2 yrs; then once per contract year up to greater of 5% or Medical Care CPI-U, 30 days notice | U21: Not stated | V21: Primary vendor: 80%+ of annual rental spend for Attachment A equipment types; after 60-day cure, market rates apply | W21: Net 30; late interest 1.5%/month (18%/yr); credit hold/repossession rights | X21: Customer liable for loss/damage repair/replacement and must insure at replacement cost; mutual indemnity; no consequential damages; USME CGL $1M/$3M | Y21: Covers Lynchburg General, Virginia Baptist, Centra Specialty Hospital (Lynchburg, VA). EMR integration at no charge. Virginia law. | Z21: High | AA21: Text
A22: CHOMP (Montage Health) | B22: Community Hospital of the Monterey Peninsula | C22: Community Hospital of the Monterey Peninsula (CHOMP) | D22: CHOMP_BTS_Exp_1_31_2026.docx | E22: Master/Rental Agreement | F22: BTS Rental, MME Rental | G22: Direct (Vizient Tier 4 pricing referenced) | H22: US Med-Equip, LLC | I22: 2022-10-11 | J22: 2025-10-11 initial; auto-renewed to 2026-10-11 | K22: 45941 | L22: Contract text | M22: 46306 | N22: =IF(M22<>"",M22-Summary!$C$3,IF(K22="","",K22-Summary!$C$3)) -> 1 | O22: Active | P22: 3 years | Q22: Auto-renews successive 1-yr terms | R22: Either party without cause, 30 days written notice | S22: Vizient Tier 4 daily rates per Attachment A (bariatric beds, low beds, Posey/Freedom Safe beds, transfer devices); consignment, no charge until used | T22: Not stated | U22: None stated; value-adds include 25% rental equity credit toward buyout and 50% lost-equipment buyout credit | V22: Primary vendor: 90%+ of annual rental spend for Attachment B facilities | W22: Net 30; USME may repossess on non-payment; customer pays collection/attorney fees | X22: Customer liable for loss/damage and abuse repairs; full new-unit cost if not returned in good condition; mutual indemnity; USME CGL $1M/$3M; Texas law, Harris County venue | Y22: Consigned peak-use BTS/bariatric equipment at CHOMP. Filename says Exp 1/31/2026 but text gives 3-yr term from 10/11/2022 with auto-renewal; primary vendor clause text says MME although equipment is BTS. CHOMP BTS amendment exp 9/30/2027 also on file. | Z22: Medium | AA22: Text
A23: CHOMP (Montage Health) | B23: Community Hospital of the Monterey Peninsula | C23: Community Hospital of the Monterey Peninsula (CHOMP) | D23: CHOMP amedment BTS_Exp_09_30_2027.pdf | E23: Amendment | F23: BTS Rental | G23: Direct | H23: US Med-Equip, LLC | I23: 2025-09-01 | J23: 2027-09-30 | K23: 46660 | L23: Contract text | N23: =IF(M23<>"",M23-Summary!$C$3,IF(K23="","",K23-Summary!$C$3)) -> 355 | O23: Active | P23: Not stated (extension of agreement dated 2025-08-13) | Q23: Not stated; further changes by mutual written amendment | R23: Per underlying agreement (not stated here) | S23: Daily rates per Attachment A: VersaTech 1100 ULB Drive $82.22; VersaTech 600 2.0 / 600 ULB $29.00; Rotec VersaTech 1100 bariatric low bed $57.00 | T23: Not stated | U23: Not stated | V23: Not stated | W23: Not stated | X23: Not stated | Y23: Extends Equipment Rental Agreement (contract UCIMC1012022TH, dated 2025-08-13) to 9/30/2027 and adds bariatric bed items. Contract number appears reused from a UCI template; verify. Amendment section 1 text truncated. | Z23: Medium | AA23: OCR
A24: CHRISTUS Health | B24: CHRISTUS Health | C24: Christus Health | D24: CHRISTUS Refurb Purchase Agreement exp_12_31_2021_auto renew.pdf | E24: Purchase/Sale Agreement | F24: Refurb Equipment Sales, Biomed/Repair Service | G24: Direct | H24: US Med-Equip, Inc. | I24: 2017-01-01; Amendment 2018-07-24 | J24: 2021-12-31 initial; auto-renews 1-yr terms (current term to 2026-12-31 if not terminated) | K24: 44561 | L24: Contract text | M24: 46387 | N24: =IF(M24<>"",M24-Summary!$C$3,IF(K24="","",K24-Summary!$C$3)) -> 82 | O24: Active | P24: 5 years | Q24: Auto-renews successive 1-yr terms | R24: Either party without cause on 30 days written notice; breach w/15-day cure; Facility immediate for cause | S24: Fixed purchase prices per Exhibit A/Attachment 1 (refurb/new Philips, Physio, Zoll defibs; flat repair after warranty); $125/hr bench rate non-warranty | T24: Supplier provides then-current published list price each Jan 1; discounts per table | U24: Not stated | V24: None stated | W24: Monthly invoicing to CHRISTUS AP; terms not legible in excerpt | X24: Broad supplier indemnity; insurance GL $1M/$2M, auto $1M, E&O $1M, cyber $10M, umbrella $1M; no assignment w/o consent; 5-yr/12-mo bench warranties | Y24: Refurbished defibrillator sales and repair agreement; 2018 amendment added products, pricing and participating facilities. Evergreen renewal per text. | Z24: Medium | AA24: OCR
A25: CHRISTUS Health | B25: CHRISTUS Health | C25: Christus Health | D25: CHRISTUS-US Med Equip-Respiratory Subordinate Agreement_Exp01_04_29.pdf | E25: Purchase/Sale Agreement | F25: Respiratory, Biomed/Repair Service | G25: Direct | H25: US Med-Equip LLC | I25: 2026-01-05 | J25: 2029-01-04 | K25: 47122 | L25: Contract text | N25: =IF(M25<>"",M25-Summary!$C$3,IF(K25="","",K25-Summary!$C$3)) -> 817 | O25: Active | P25: 3 years | Q25: None stated (governed by Master Purchasing Agreement eff. 2026-01-05) | R25: Not stated in subordinate agreement (Master Agreement controls); auto-terminates for facilities that cease to qualify | S25: Fixed purchase prices per Attachment 1 (e.g., Airon pNeuton Model A ventilator start-up kit $9,841.40); trade-in allowances at USME discretion | T25: Not stated | U25: Not stated | V25: Not stated; quotation-compliance warranty with refund of overcharges | W25: Not stated (Applicable Rate for late = lesser of 1.5%/mo or legal max) | X25: SLA: phone support within 30 min (10% monthly service credit if missed); Urban FSE onsite 2 hrs (service extension penalty); pass-through OEM uptime/warranty; 12-mo parts warranty; perpetual software license; IT access controls | Y25: Subordinate purchasing agreement under CHRISTUS Master Purchasing Agreement for respiratory/ventilator products (Airon pNeuton transport ventilators) at CHRISTUS St. Michael (Texarkana/Atlanta TX) facilities. Service/PM obligations attach if service purchased. | Z25: Medium | AA25: OCR
A26: CHRISTUS Health | B26: CHRISTUS Health | C26: Christus Health | D26: CHRISTUS-US Med Equip-Master Agreement_Exp01_04_29.pdf | E26: Master/Rental Agreement | F26: MME Rental, Biomed/Repair Service, Refurb Equipment Sales | G26: Direct | H26: US Med-Equip LLC | I26: 2026-01-05 | J26: 2036-01-04 per text (10-yr term); filename says 01/04/29 | K26: 49678 | L26: Contract text | N26: =IF(M26<>"",M26-Summary!$C$3,IF(K26="","",K26-Summary!$C$3)) -> 3373 | O26: Active | P26: 10 years; survives while any Subordinate Agreement remains in effect | Q26: None stated | R26: No convenience termination stated; either party for material breach (30-day cure); CHRISTUS immediate for cause (safety, reputation, exclusion, false reps) or regulatory issues | S26: Master Purchasing Agreement; pricing set in separate Subordinate Agreements per Facility | T26: Firm pricing: no increases during Subordinate Agreement Term unless stated therein; decreases must be offered to all Facilities | U26: Not stated | V26: None stated; Facilities not obligated to buy across Subordinate Agreements; failure to supply -> USME pays price difference for Competing Product | W26: Facility pays within 30 days of receipt of compliant invoice; equipment purchases 80% on delivery / 20% on acceptance; no handling fees | X26: MFN: prices/terms must equal or beat any other customer, with refunds of difference; insurance: GL $1M/$2M, auto $1M, E&O $1M, cyber $1M, umbrella $5M; assignment needs consent (affiliate/M&A allowed with notice) | Y26: Umbrella MSA signed 1/6/2026 governing all CHRISTUS Subordinate Agreements; Catholic ERDs, HIPAA, MDS2 forms due within 30 days of each Subordinate Agreement. Filename expiry (1/4/2029) conflicts with 10-yr term in text; may reflect a Subordinate Agreement term. | Z26: High | AA26: OCR
A27: ClearSky Health | B27: ClearSky Health | C27: ClearSky Health | D27: ClearSky Health MME BTS Exp_5_31_26_LR.pdf | E27: Master/Rental Agreement | F27: MME Rental | G27: Direct | H27: US Med-Equip, LLC | I27: 2023-06-01 | J27: 2027-05-31 (current auto-renewal term; initial term ended 2026-05-31) | K27: 46538 | L27: Contract text | N27: =IF(M27<>"",M27-Summary!$C$3,IF(K27="","",K27-Summary!$C$3)) -> 233 | O27: Active | P27: 3 years | Q27: Auto-renews successive 1-yr terms | R27: Either party, 30 days written notice without cause (any time) | S27: Monthly rental rates per Attachment A; Primary Vendor pricing | T27: Not stated | U27: Not stated | V27: Primary Vendor: 90%+ of annual MME rental spend for Attachment B facilities | W27: Net 30 | X27: Customer liable for loss/damage and abuse repairs plus USME enforcement/collection costs; full new-unit cost if not surrendered; USME CGL $1M/$3M; customer may not assign without consent | Y27: Contract 06082023LR with New Mexico rehab operator. Only MME monthly pricing visible in OCR (no BTS pricing found despite 'MME BTS' filename). Attachment B facility list not captured. | Z27: Medium | AA27: OCR
A28: ClearSky Health | B28: ClearSky Health | C28: ClearSky Health | D28: ClearSky_Agreement_Exp_9_30_27_2_29_28.pdf | E28: Master/Rental Agreement | F28: MME Rental, BTS Rental | G28: Vizient CE7782 (MME Tier 3) and Vizient CE9205 (BTS Tier 3) | H28: US Med-Equip, LLC | I28: 2025-05-06 | J28: 2028-05-05 (initial term; auto-renews) | K28: 46878 | L28: Contract text | N28: =IF(M28<>"",M28-Summary!$C$3,IF(K28="","",K28-Summary!$C$3)) -> 573 | O28: Active | P28: 3 years | Q28: Auto-renews successive 1-yr terms | R28: After Initial Term only: either party, without cause, 60 days written notice | S28: Vizient CE7782 Tier 3 (90% commitment) for MME; Vizient CE9205 Tier 3 (80% commitment) for beds/surfaces; fixed for term | T28: Fixed for term (pricing effective for term of contract) | U28: Not stated | V28: Primary vendor: 90% of MME rental spend, 80% of BTS rental spend; 60-day cure then list pricing for remaining term | W28: Net 30 via ACH/wire; late interest 1.5%/month (18%/yr); credit hold and list pricing on non-payment | X28: Customer liable for loss/damage and must insure equipment at replacement cost; mutual indemnity; consequential damages exclusion; CGL $1M/$3M; customer may not assign | Y28: Filename dates (9/30/27, 2/29/28) do not match text: 3-yr term from 5/6/2025 implies initial term ending 5/5/2028. No convenience exit during first 3 years. | Z28: High | AA28: Text
A29: Cleveland Clinic | B29: The Cleveland Clinic Foundation d.b.a. Cleveland Clinic | C29: Cleveland Clinic | D29: Cleveland Clinic_Exp_7_31_28.pdf | E29: Master/Rental Agreement | F29: BTS Rental | G29: Direct (CCF Contract ID 4330960) | H29: US Med-Equip, LLC | I29: 2025-08 (signed 8/8-8/11/2025; term starts on installation) | J29: 2028-07-31 (per filename; 3 years from installation) | K29: 46965 | L29: Contract text | N29: =IF(M29<>"",M29-Summary!$C$3,IF(K29="","",K29-Summary!$C$3)) -> 660 | O29: Active | P29: 3 years from installation | Q29: Extension by written agreement of parties | R29: Customer-only: Lessee with or without cause on 30 days notice; either party for uncured breach (30 days) or insolvency | S29: Exhibit A fixed rates: Advanced Wave Mattress $32.00, Advanced Wave Mattress XMS $42.00 (Rotec VersaTech beds also in scope) | T29: Not stated | U29: Not stated | V29: None stated | W29: Not stated | X29: Lessee pays FMV replacement for loss/theft after acceptance; Lessor liable for its negligence; mutual indemnity; consequential damages excluded; no assignment w/o consent; recall notice 24 hrs | Y29: Rental of Advanced Wave mattresses and Rotec VersaTech beds to Cleveland Clinic and 10 eligible facilities (incl. Weston, FL). Customer can exit on 30 days. | Z29: High | AA29: OCR
A30: CommonSpirit Health | B30: CommonSpirit Health (FKA CHI, Dignity Health) and Affiliates | C30: CommonSpirit | D30: CSH-MM-156_CommonSpirit_Exp_3_31_28.pdf | E30: Master/Rental Agreement | F30: MME Rental, Respiratory | G30: Direct (CSH-MM-156) | H30: US Med Equip, LLC | I30: 2025-04-01 | J30: 2028-03-31 | K30: 46843 | L30: Contract text | N30: =IF(M30<>"",M30-Summary!$C$3,IF(K30="","",K30-Summary!$C$3)) -> 538 | O30: Active | P30: 3 years | Q30: None unless mutually agreed in writing | R30: Either party without cause, 60 days written notice; CSH may terminate immediately on Vendor change of control or repeated SLA failures | S30: CSH-specific Tier 1 daily/monthly rates per Section 2 (model-level list), 28-day monthly cap; patient beds excluded | T30: Fixed first 12 months; then max once per calendar year with documentation and written amendment, capped at lesser of 3% or CPI-U | U30: 3% rebate to CSH entities, paid quarterly within 30 days of quarter end | V30: Not stated (no volume commitment found) | W30: Net 30 from receipt of undisputed invoice via EFT; invoices >180 days late not payable; no late fees on rejected invoices | X30: IDN MFN price warranty (breach = termination right); FMV damage process; delivery 2 hrs + drive time; insurance up to $5M; change-of-control termination; transition assistance | Y30: National peak-use rental agreement (infusion, monitoring, respiratory, infant care) covering all CommonSpirit facilities. Expressly supersedes and voids Premier PP-NS-1662 and related pricing for CSH. | Z30: High | AA30: Text
A31: CommonSpirit Health | B31: CommonSpirit Health (on behalf of itself and affiliates) | C31: CommonSpirit | D31: CSH-MM-158_CommonSpirit_BTS_Exp_3_31_28.pdf | E31: Master/Rental Agreement | F31: BTS Rental, Restraints/Posey | G31: Direct (CSH-MM-158) | H31: US Med-Equip, LLC | I31: 2025-04-01 | J31: 2028-03-31 | K31: 46843 | L31: Contract text | N31: =IF(M31<>"",M31-Summary!$C$3,IF(K31="","",K31-Summary!$C$3)) -> 538 | O31: Active | P31: 3 years | Q31: None stated | R31: Either party, 60 days written notice without cause; immediate for material breach | S31: National daily rental rates per Section 2 fee schedule | T31: Conflict: Sec 2 fixed 12 months then 1x/yr capped at lesser of 3% or CPI-U via written amendment; Std T&C 2.2 says fixed for initial term | U31: 3% rebate on service fees paid quarterly within 30 days (Schedule C); no GPO admin fee paid | V31: None stated | W31: Net 30 from invoice receipt via EFT; no late fees on good-faith rejected invoices | X31: Vendor liable for damage it causes; mutual consequential damages waiver w/ carve-outs; audit reimbursement if overcharge >=5%; assignment requires consent; extensive personnel screening; insurance incl. $3M/occurrence line | Y31: National BTS agreement for CommonSpirit facilities; replaces prior arrangements. Requires corporate account manager and heavy vendor-credentialing compliance. | Z31: High | AA31: Text
A32: Cook Children's | B32: Cook Children's Medical Center | C32: Cook Children's | D32: Cook Children MSA BTS Repair_Exp_10_19_23_Auto_2026.pdf | E32: Master/Rental Agreement | F32: BTS Rental, Biomed/Repair Service | G32: Direct | H32: US Med-Equip, LLC | I32: 2023-10-19 | J32: 2026-10-19 (or later expiration of any open SOW) | K32: 46314 | L32: Contract text | N32: =IF(M32<>"",M32-Summary!$C$3,IF(K32="","",K32-Summary!$C$3)) -> 9 | O32: Active | P32: 3 years (or until all SOWs end, if later) | Q32: No auto-renewal stated; MSA survives until all SOWs expire | R32: No convenience termination; breach with 60-day cure, insolvency, force majeure >30 days (10 days notice), mutual agreement; USME may terminate on customer change of control | S32: Per SOW Program Budget (no SOW attached) | T32: Not stated (Program Budget changes require mutual written consent) | U32: Not stated | V32: Expressly non-exclusive | W32: Net 30 from invoice receipt (undisputed); late interest lesser of 1.5%/mo or TX max, compounded; collection costs | X32: USME liability capped at 12 months of fees for applicable SOW; no consequential damages; USME indemnifies for equipment damage in its custody; 12-mo non-solicit; USME CGL $1M/$3M | Y32: Framework MSA for BTS rental and repair services; commercial terms live in SOWs not included in file. Filename 'Exp_10_19_23' is effective date; text gives 3-year term to 10/19/2026, expiring in 9 days absent active SOW. | Z32: High | AA32: OCR
A33: County of Los Angeles | B33: County of Los Angeles (Department of Health Services) | C33: County of Los Angeles | D33: LA County RT Biomed Exp 6.30.2028.pdf | E33: Service Agreement/SOW | F33: Biomed/Repair Service, Respiratory | G33: Direct | H33: US Med-Equip, LLC | I33: 2024-10-17 | J33: 2028-06-30 | K33: 46934 | L33: Contract text | N33: =IF(M33<>"",M33-Summary!$C$3,IF(K33="","",K33-Summary!$C$3)) -> 629 | O33: Active | P33: ~3.7 years (2024-10-17 to 2028-06-30) | Q33: County Director may extend at sole discretion on written notice | R33: County only, for convenience, at least 10 days notice; also non-appropriation of funds | S33: Maintenance fees per Exhibit B Rate Schedule (per-model PM/overhaul rates for respiratory equipment); hourly rate for additional services via Work Orders | T33: Rates effective through 2028-06-30; changes only by County-prepared amendment | U33: Not stated | V33: Non-exclusive master agreement | W33: Invoice in arrears; no payment for services after expiration | X33: 95% uptime guarantee with tiered credits (to $500); <80% uptime 5+ days = default; 4-hr service response; liquidated damages; broad indemnity; County approval for assignment/merger/change of control | Y33: Master Agreement H-711223 for Respiratory Equipment Maintenance and Repair Services at DHS facilities. Must notify DHS 6 months before expiration. Heavy county compliance requirements (background checks, jury service, etc.). | Z33: High | AA33: Text
A34: County of Los Angeles (DHS) | B34: County of Los Angeles, Department of Health Services | C34: County of Los Angeles | D34: County of Los Angeles_Service agreement_Exp_6_30_2028.pdf | E34: Service Agreement/SOW | F34: Biomed/Repair Service, Respiratory | G34: Direct (Master Agreement H-711223, via RFR) | H34: US Med-Equip, LLC | I34: 2024-10-17 | J34: 2028-06-30 | K34: 46934 | L34: Contract text | N34: =IF(M34<>"",M34-Summary!$C$3,IF(K34="","",K34-Summary!$C$3)) -> 629 | O34: Active | P34: ~3.7 years (through June 30, 2028) | Q34: Director may extend term at sole discretion with prior written notice | R34: County-only, for convenience at sole discretion, effective >=10 days after notice; also for default, non-appropriation, insolvency | S34: Exhibit B Rate Schedule: per-model PM/inspection fees by service category (e.g., Servo i PM $1,313) plus hourly rate for Additional Services; Work Orders capped at Maximum Fixed Price | T34: Rates effective through 2028-06-30; no escalator stated | U34: Not stated | V34: Non-exclusive; payment only for County-approved work | W34: Invoice monthly in arrears within 30 days of month-end; County approval required; no pay for post-expiration services | X34: Broad County indemnity (incl. confidentiality and IP); liquidated damages; 4-hr service call response; County approval for assignment/merger/change of control; background checks; CGL insurance required | Y34: Respiratory equipment maintenance and repair at DHS facilities (e.g., Harbor-UCLA). Heavy public-agency compliance burden; USME must notify DHS 6 months before expiry. | Z34: High | AA34: Text
A35: County of San Mateo | B35: County of San Mateo on behalf of San Mateo Medical Center | C35: San Mateo Medical Center | D35: San Mateo_Equip Rental Agmt_MME BTS_Exp 11_30_27.pdf | E35: Master/Rental Agreement | F35: MME Rental, BTS Rental | G35: Direct | H35: US Med-Equip, LLC | I35: 2024-12-01 | J35: 2027-11-30 | K35: 46721 | L35: Contract text | N35: =IF(M35<>"",M35-Summary!$C$3,IF(K35="","",K35-Summary!$C$3)) -> 416 | O35: Active | P35: 3 years | Q35: May be extended by amendment | R35: Customer may terminate at any time (notice text garbled); customer may terminate immediately for lack of funding; 60-day breach cure | S35: Daily/monthly rates per pricing attachment; contract # KS08052025SMMC | T35: Fixed until 2nd anniversary; then max 1x/yr by greater of 5% or CPI-U | U35: Not stated | V35: Primary Vendor section blank | W35: Net 30 | X35: Total payments capped at $200,000; customer liable for loss/damage; mutual indemnity; additional-insured and primary insurance requirements; county ordinance compliance (living wage, jury service, $2,500 LDs); CA law | Y35: County contract with $200K not-to-exceed cap that could limit billing. Text partially garbled. | Z35: Medium | AA35: Text
A36: Craig Hospital | B36: Craig Hospital | C36: Craig Hospital | D36: Craig Hospital Posey agreement Exp_08_02_29.pdf | E36: Master/Rental Agreement | F36: Restraints/Posey | G36: Direct | H36: US Med-Equip, LLC | I36: 2026-08-03 | J36: 2029-08-02 | K36: 47332 | L36: Contract text | N36: =IF(M36<>"",M36-Summary!$C$3,IF(K36="","",K36-Summary!$C$3)) -> 1027 | O36: Active | P36: 3 years | Q36: Auto-renews successive 1-yr terms | R36: Customer may terminate without cause on 60 days notice during Initial Term; either party on 60 days after Initial Term | S36: Monthly rates per Attachment A: Posey 8060 Enclosure $700/month (qty 10); Primary Vendor pricing | T36: Not stated | U36: Not stated | V36: Primary Vendor: 90%+ of annual rental spend; 60-day cure, then list pricing for remainder of term | W36: Net 30 via ACH/wire; interest at max legal rate on past due; credit hold and list pricing on nonpayment | X36: Customer liable for loss/damage only from its negligence/misuse; mutual indemnity; no consequential damages; USME CGL $1M/$3M; customer insures replacement cost; customer may not assign | Y36: New 2026 Posey enclosure rental agreement (10 units). Customer has a one-sided termination-for-convenience right during the initial term, which undercuts the 3-year term. | Z36: High | AA36: OCR
A37: CuraHealth | B37: Curahealth, LLC | C37: CuraHealth | D37: CuraHealth_MME_Exp12_3_2023_auto_renew.pdf | E37: Master/Rental Agreement | F37: MME Rental, Respiratory | G37: Vizient (Preferred Partnership 90% LOC Tier 3 pricing; no contract # stated) | H37: US Med-Equip, LLC | I37: 2020-12-04 | J37: 2023-12-03 initial; auto-renewed, current term likely through 2026-12-03 | K37: 45263 | L37: Contract text | M37: 46359 | N37: =IF(M37<>"",M37-Summary!$C$3,IF(K37="","",K37-Summary!$C$3)) -> 54 | O37: Active | P37: 3 years | Q37: Auto-renews successive 1-yr terms unless either party cancels in writing 30 days before term end | R37: No termination for convenience; for uncured breach (60-day cure) or insolvency; non-renewal with 30 days notice | S37: Monthly rental rates per Attachment A at Vizient Preferred Partnership 90% LOC Tier 3 pricing; Contract # CH 10122020JD | T37: Not stated | U37: Not stated; equity option: 25% of monthly rental paid (up to 12 months) credited toward purchase | V37: Customer names USME primary first-call vendor for MME rental in exchange for Vizient Preferred Partnership pricing | W37: Monthly rent due on the 1st of each month; customer pays collection/attorney fees on default | X37: Customer responsible for safekeeping, loss/damage and abuse repairs; full replacement cost if not returned in good condition; GL $1M/$3M; mutual indemnity; customer may not assign | Y37: Monthly MME/respiratory rental (ventilators, pumps, monitors, CPMs) to Curahealth. Auto-renewal keeps it in force absent a non-renewal notice; next renewal date ~12/3/2026, cancel notice by ~11/3/2026. | Z37: Medium | AA37: OCR
A38: DaVita | B38: DaVita Inc. | C38: Davita | D38: Davita _Exp_5_31_28.pdf | E38: Amendment | F38: Refurb Equipment Sales, MME Rental, Biomed/Repair Service | G38: Direct | H38: US Med-Equip LLC (written 'US Medi-Equip LLC') | I38: 2025-07-08 (Second Amendment; base Product Purchase Agreement eff. 2021-09-01) | J38: 2028-05-31 | K38: 46904 | L38: Contract text | N38: =IF(M38<>"",M38-Summary!$C$3,IF(K38="","",K38-Summary!$C$3)) -> 599 | O38: Active | P38: Not stated (term extended through 2028-05-31) | Q38: Not stated | R38: Not stated in amendment (per base agreement) | S38: Restated Exhibit A: refurb pump sales (Spectrum $1,035.71, Medfusion 3500 $1,821.43), IV sets, rentals $49-$132.44/month, service $125/hr, PM $100 | T38: Not stated | U38: Not stated; early payment discount removed | V38: Not stated | W38: Net 30 from AP receipt; monthly invoicing; customer may withhold disputed amounts; early-pay discount removed | X38: Title passes on delivery; DaVita pays shipping; orders ship ground within 24 hrs; free training and manuals required | Y38: Second Amendment extends DaVita product purchase agreement to 5/31/2028 and replaces pricing; covers refurbished infusion pump sales, disposables, pump rentals and repair service. Entity name misspelled in the preamble. | Z38: High | AA38: Text
A39: Department of Veterans Affairs | B39: Department of Veterans Affairs, Network Contract Office 17 (Amarillo VA Medical Center) | C39: Veteran Affairs Amarillo Medical Center | D39: Amendmen for VA Agreement_06.16.2026.pdf | E39: Amendment | F39: Not stated | G39: Direct (VA contract/order 36C25726R0023 per OCR; Mod P0002) | H39: US Med-Equip, LLC | I39: 2026-06-16 (contractor signature date; effective date block references 16c) | J39: Not stated | L39: Unknown | N39: =IF(M39<>"",M39-Summary!$C$3,IF(K39="","",K39-Summary!$C$3)) | O39: Active | P39: Not stated | Q39: Not stated | R39: Noncompliance with FAR 52.222-90 may result in cancellation, termination or suspension | S39: Not stated | T39: Not stated | U39: Not stated | V39: Not stated | W39: Not stated | X39: Adds FAR 52.222-90 (no racially discriminatory DEI activities); compliance material to payment under False Claims Act; flow-down to subcontractors required | Y39: SF-30 Modification P0002 solely incorporating FAR 52.222-90 per EO 14398; no other changes. Signed by Clay Rose 6/16/2026; underlying VA contract terms not included. | Z39: Medium | AA39: OCR
A40: DispatchHealth | B40: Dispatch Health Management, LLC | C40: Dispatch Health | D40: Dispatch_Health_Amendment_exp 06_30_29.pdf | E40: Extension | F40: MME Rental, BTS Rental, Respiratory | G40: Direct | H40: US Med-Equip, LLC | I40: 2026-06-03 (amendment); extension term starts 2026-07-01 | J40: 2029-06-30 | K40: 47299 | L40: Contract text | N40: =IF(M40<>"",M40-Summary!$C$3,IF(K40="","",K40-Summary!$C$3)) -> 994 | O40: Active | P40: 3-year extension (base agreement dated 2025-07-02) | Q40: Not stated | R40: Per underlying agreement (not stated in amendment) | S40: Exhibit A replaced: MME (oxygen concentrators, Kangaroo pump, Philips M10) and BTS (Freedom 500 bed, bariatric wheelchairs) daily/monthly rates | T40: Not stated | U40: Not stated | V40: Not stated | W40: Not stated | X40: Not stated | Y40: Extends Dispatch Health rental agreement 7/1/2026-6/30/2029, replaces pricing, and adds 16 locations across OH, GA, TX, CO, NV, FL, AZ, VA, WA (Exhibit B). Signed 7/31/2026 by James Duvall (USME). | Z40: High | AA40: Text
A41: Encompass Health | B41: Encompass Health Corporation | C41: Encompass Health | D41: Encompass_Exp_11_12_2023_auto_renewal.pdf | E41: Master/Rental Agreement | F41: MME Rental, Respiratory | G41: Vizient CE7073 | H41: US Med-Equip, LLC | I41: 2020-11-12 | J41: 2023-11-12 initial; auto-renews 1-yr (current term to ~2026-11-12) | K41: 45242 | L41: Contract text | M41: 46338 | N41: =IF(M41<>"",M41-Summary!$C$3,IF(K41="","",K41-Summary!$C$3)) -> 33 | O41: Active | P41: 3 years | Q41: Auto-renews 1-yr terms unless cancelled 30 days before term end | R41: Either party, 60 days written notice without cause | S41: Monthly rates per Attachment A at Vizient Tier 3 Preferred Partnership (90% LOC) pricing | T41: Fixed for term (reductions only) | U41: Vizient admin fees apply; 25% equity discount on rental dollars (up to 12 months) toward purchase | V41: Dual-source MME vendor designation; credit standing required, DSO <= 60 days | W41: Due 1st of each month; repossession right on non-payment | X41: Customer bears loss/damage and abuse repairs; USME indemnifies for customer use of equipment; CGL $1M/$3M; assignment requires consent; Delaware law | Y41: Contract # EH 09152020JD. Vizient terms apply where more favorable to customer. Next renewal ~2026-11-12; cancellation window closes ~mid-Oct 2026. | Z41: Medium | AA41: OCR
A42: Encompass Health | B42: Encompass Health Rehabilitation Hospital of Northwest Tucson, L.P. | C42: Encompass Tucson | D42: Encompass Tucson_MME_BTS_Exp_3_31_2024_LR.pdf | E42: Master/Rental Agreement | F42: MME Rental, BTS Rental, Respiratory, Restraints/Posey | G42: Direct | H42: Freedom Medical, Inc. | I42: 2019-06-14 | J42: 2024-03-31 (now rolling 30-day renewals) | K42: 45382 | L42: Contract text | N42: =IF(M42<>"",M42-Summary!$C$3,IF(K42="","",K42-Summary!$C$3)) -> -923 | O42: Active | P42: Through 2024-03-31 (~4.8 years) | Q42: Auto-renews 30-day periods unless 30 days notice | R42: Either party on 30 days written notice after initial term; customer may terminate immediately for quality issues, rep breach, or hospital sale/closure | S42: Fixed daily/monthly rates per Exhibit A; beds at Tier 5 pricing schedule | T42: Not stated | U42: Not stated | V42: Not stated | W42: Net 30; invoices due by 10th of following month; invoices received 1+ year after service deemed paid | X42: Customer bears loss/damage at replacement cost; mutual negligence indemnity; no assignment without consent (FMI-to-USME assignment risk); insurance CGL $1M/$2M, auto $1M, umbrella $5M | Y42: Legacy Freedom Medical contract for single Tucson rehab hospital; initial term ended 3/31/2024 and it has been running month-to-month. Filename '_LR' consistent; agreement names FMI, not USME. | Z42: Medium | AA42: Text
A43: Englewood Post Acute | B43: Cherry Hills Healthcare, Inc. dba Englewood Post Acute and Rehabilitation | C43: Englewood | D43: Englewood Post Acute_Exp_04_18_2025_auto_2027.pdf | E43: Master/Rental Agreement | F43: BTS Rental | G43: Direct | H43: Freedom Medical, Inc. | I43: 2022-04-19 | J43: 2025-04-18 initial; renewals to 2027-04-18 | K43: 45765 | L43: Contract text | N43: =IF(M43<>"",M43-Summary!$C$3,IF(K43="","",K43-Summary!$C$3)) -> -540 | O43: Active | P43: 3 years | Q43: Two consecutive 12-month renewals unless either party gives 60 days notice of non-renewal | R43: Either party without cause, 30 days written notice | S43: Daily rental rates per Exhibit A (Freedom Comfort/Advanced Wave mattresses, $8.25-$55.00/day) | T43: Firm for 36 months; thereafter not stated | U43: None | V43: Customer to use FMI as primary medical equipment rental provider (no % stated) | W43: Net 30 from invoice; 1.5%/month on invoices 60+ days past due; no offset; billing disputes within 90 days | X43: Customer liable for loss/damage from receipt to return at current market value; FMI liability limited to repair/replace/refund, no consequential damages; mutual indemnity; arbitration | Y43: Legacy Freedom Medical therapeutic surface rental agreement for a post-acute facility. Assumed in second renewal period through 4/18/2027 absent non-renewal notice. | Z43: High | AA43: Text
A44: Erlanger Health | B44: Chattanooga-Hamilton County Hospital Authority d/b/a Erlanger Health System | C44: Erlanger Health | D44: Erlanger_MME_Exp_10_7_2021_Auto renew.pdf | E44: Master/Rental Agreement | F44: MME Rental, Respiratory | G44: Vizient (Access / LOC Tier 2 / LOC Tier 3 pricing; contract no. not stated) | H44: US Med-Equip, Inc. | I44: 2018-10-08 (OCR date partial) | J44: 2021-10-07 initial; auto-renews 1-yr (current term to ~2027-10-07) | K44: 44476 | L44: Contract text | M44: 46667 | N44: =IF(M44<>"",M44-Summary!$C$3,IF(K44="","",K44-Summary!$C$3)) -> 362 | O44: Active | P44: 3 years | Q44: Auto-renews 1-yr terms unless cancelled 30 days before term end | R44: No termination for convenience; breach (60-day cure) or insolvency only | S44: Daily/monthly rates per Attachment A by Vizient Access, LOC Tier 2 and LOC Tier 3 columns | T44: Not stated | U44: 25% equity discount on rental dollars (up to 12 months) toward purchase | V44: Not stated | W44: Net 30 (text also references net 60 - conflicting); PO required per delivery | X44: Customer bears loss/damage; delivery included F.O.B. destination; USME pays medical device tax; full new-unit replacement charge if not returned in good condition; CGL $1M/$3M | Y44: Contract # 070118THCHCHA covering Hamilton County TN facilities. Remains in effect via 1-yr auto-renewals absent cancellation. | Z44: Medium | AA44: OCR
A45: Grandview Medical Center (CHS / CHSPSC) | B45: Affinity Hospital LLC d/b/a Grandview Medical Center | C45: Grandview Medical Center | D45: Grandview Asset Mgt_rental_Exp_3_31_2028_LR.pdf | E45: Service Agreement/SOW | F45: Asset Mgmt/On-site, MME Rental, Biomed/Repair Service, Respiratory | G45: HPG-7093 (rental pricing) with CHSPSC Group SIP | H45: US Med-Equip (US Med-Equip LLC) | I45: 2023-04-01 | J45: Not explicitly stated; 5-year commitment implies 2028-03-31 | K45: 46843 | L45: Contract text | N45: =IF(M45<>"",M45-Summary!$C$3,IF(K45="","",K45-Summary!$C$3)) -> 538 | O45: Active | P45: 5 years | Q45: Not stated | R45: Either party without cause, 90 days written notice; $60,000 termination fee if Grandview terminates without cause in first 12 months | S45: Asset management fixed fee $37,397/month plus $10,000 one-time startup; rental at HPG-7093/CHSPSC SIP pricing; respiratory PM price list at HPG price (discount to list) | T45: Rental pricing held firm through term; more favorable renewed HPG/SIP pricing prevails | U45: Not stated | V45: 5-year commitment; 4 on-site USME staff (team lead + 3) covering 1,910 hospital-owned devices | W45: Not stated | X45: USME indemnifies Grandview; insurance CGL $1M/$2M, professional $1M/$3M, cyber $5M/$10M, product $1M/$3M; loss/damage on party at fault; Grandview may terminate if force majeure >30 days | Y45: Proposal-form agreement (dated 2023-02-28) for on-site asset management with STAR Trax RFID at Grandview. Filename _LR; expiration inferred from 5-yr term. | Z45: Medium | AA45: Text
...

Sheet Action Watchlist
A1: Customer Group | B1: Counterparty (as written) | C1: Folder | D1: File Name | E1: Doc Type | F1: Service Lines | G1: GPO / Contract # | H1: USME Entity | I1: Effective Date | J1: Expiration (as stated) | K1: Expiration Date | L1: Exp. Date Source | M1: Projected Term End (auto-renew roll-fwd) | N1: Days to Expiry | O1: Status | P1: Initial Term | Q1: Renewal | R1: Termination | S1: Pricing Basis | T1: Price Increase / Escalator | U1: Rebate / Admin Fee | V1: Commitment / Exclusivity | W1: Payment Terms | X1: Liability / Risk Terms | Y1: Key Notes | Z1: Confidence | AA1: Text Source
A2: AdventHealth | B2: Adventist Health System Sunbelt Healthcare Corporation d/b/a AdventHealth | C2: AdventHealth | D2: PP-NS-1565 US Med-Equip A1.docx.pdf | E2: Amendment | F2: BTS Rental, Other | G2: Premier PP-NS-1565 | H2: US Med-Equip, LLC | I2: 2025-10-01 | J2: Not stated (follows underlying PP-NS-1565 supplement agreement) | L2: Unknown | N2: =IF(M2<>"",M2-Summary!$C$3,IF(K2="","",K2-Summary!$C$3)) | O2: Active | P2: Not stated | Q2: Not stated | R2: Not stated | S2: Adds one item to Schedule 1: Stryker Medical Extender Kit (item 59739) at $13.11/EA | T2: Not stated | U2: Not stated | V2: Not stated | W2: Not stated | X2: Not stated | Y2: Amendment 1 to AdventHealth GPO supplement agreement under Premier PP-NS-1565 adding a Stryker extender kit; signed 10/24/2025 by Doug Pytlinski (AdventHealth) and Tim Heck (USME). Term and other terms governed by the underlying supplement. | Z2: High | AA2: Text
